#VRML_SIM R2025a utf8

EXTERNPROTO "webots://projects/objects/backgrounds/protos/TexturedBackground.proto"
EXTERNPROTO "webots://projects/objects/backgrounds/protos/TexturedBackgroundLight.proto"
EXTERNPROTO "webots://projects/objects/floors/protos/CircleArena.proto"
EXTERNPROTO "webots://projects/objects/factory/containers/protos/WoodenBox.proto"

WorldInfo {
  title "Speed Control Arena"
}

Viewpoint {
  orientation -0.23 -0.01 0.97 3.24
  position 2.7 0.1 1.6
}

TexturedBackground { }
TexturedBackgroundLight { }
CircleArena { }

WoodenBox {
  translation -0.37 0.06 0.05
  rotation 0 0 1 0.5
  size 0.1 0.1 0.1
}
WoodenBox {
  translation 0.42 -0.43 0.05
  rotation 0 0 1 4.96
  size 0.1 0.1 0.1
}
WoodenBox {
  translation -0.35 -0.5 0.05
  rotation 0 0 1 5.36
  size 0.1 0.1 0.1
}
WoodenBox {
  translation 0.36 0.3 0.05
  rotation 0 0 1 5.36
  size 0.1 0.1 0.1
}
WoodenBox {
  translation -0.16 0.61 0.05
  rotation 0 0 1 5.36
  size 0.1 0.1 0.1
}

DEF ROBOT1 Robot {
  translation 0 0 0
  rotation 0 0 -1 0
  children [
    DEF MAIN_BODY Pose {
      translation 0 0 0.0415
      children [
        Shape {
          appearance PBRAppearance {
            baseColor 0.1 0.3 0.8
            roughness 1
            metalness 0
          }
          geometry Cylinder {
            height 0.08
            radius 0.045
          }
        }
      ]
    }
    HingeJoint {
      jointParameters HingeJointParameters {
        axis 0 1 0
        anchor 0 0 0.025
      }
      device [
        RotationalMotor {
          name "left wheel motor"
        }
        PositionSensor {
          name "left wheel sensor"
        }
      ]
      endPoint Solid {
        translation 0 0.045 0.025
        rotation 0 -1 0 4.98
        children [
          Pose {
            rotation -1 0 0 1.57
            children [
              Shape {
                appearance PBRAppearance {
                  baseColor 1 0 0
                  roughness 1
                  metalness 0
                }
                geometry Cylinder {
                  height 0.01
                  radius 0.025
                }
              }
            ]
          }
        ]
        name "left wheel"
        boundingObject Pose {
          rotation -1 0 0 1.57
          children [
            Shape {
              appearance PBRAppearance {
                baseColor 1 0 0
                roughness 1
                metalness 0
              }
              geometry Cylinder {
                height 0.01
                radius 0.025
              }
            }
          ]
        }
        physics Physics {
          density -1
          mass 0.05
        }
      }
    }
    HingeJoint {
      jointParameters HingeJointParameters {
        axis 0 1 0
        anchor 0 0 0.025
      }
      device [
        RotationalMotor {
          name "right wheel motor"
        }
        PositionSensor {
          name "right wheel sensor"
        }
      ]
      endPoint Solid {
        translation 0 -0.045 0.025
        rotation 0 -1 0 4.58
        children [
          Pose {
            rotation -1 0 0 1.57
            children [
              Shape {
                appearance PBRAppearance {
                  baseColor 1 0 0
                  roughness 1
                  metalness 0
                }
                geometry Cylinder {
                  height 0.01
                  radius 0.025
                }
              }
            ]
          }
        ]
        name "right wheel"
        boundingObject Pose {
          rotation -1 0 0 1.57
          children [
            Shape {
              appearance PBRAppearance {
                baseColor 1 0 0
                roughness 1
                metalness 0
              }
              geometry Cylinder {
                height 0.01
                radius 0.025
              }
            }
          ]
        }
        physics Physics {
          density -1
          mass 0.05
        }
      }
    }
    DEF FRONT_IR DistanceSensor {
      translation 0.05 0 0.062
      rotation 0 0 1 0
      name "ds0"
      lookupTable [
        0 1024 0
        0.05 1024 0
        0.15 0 0
      ]
      numberOfRays 2
      aperture 1
    }
  ]
  name "robot1"
  controller "speed_control"
  boundingObject Pose {
    translation 0 0 0.0415
    children [
      Cylinder {
        height 0.08
        radius 0.045
      }
    ]
  }
  physics Physics {
    density -1
    mass 0.5
  }
}
